Workbook
Name DaysPerMonth: Summary!$I$20
Name FreeRetDays: Summary!$I$19
Name PriceAnalytics: Summary!$I$14
Name PriceLake: Summary!$I$15
Name PriceStorage: Summary!$I$16
Name RetAnalyticsTotal: Summary!$I$17
Name RetLakeTotal: Summary!$I$18

Sheet Log Types
A1: Category | B1: Sub-category | C1: Detection | D1: Forensics & Investigation | E1: Compliance | F1: Ingestion Method | G1: Storage Target | H1: Status | I1: Log Source | J1: Table Name | K1: Cost Tier | L1: DaysWithData | M1: AvgGBperDay | N1: MinGBperDay | O1: MaxGBperDay | P1: BillableGBperDay | Q1: CHFperDay | R1: CHFperMonth | S1: LakeCHFperMonthWhenFull
A2: Endpoint / Host / EC2 | B2: EDR/XDR telemetry | C2: TRUE | D2: TRUE | E2: TRUE | F2: XDR → Sentinel integration | G2: SIEM + SIEM data lake | H2: Completed | I2: MS Defender for Endpoint | J2: DeviceEvents | K2: 1 | L2: 27 | M2: 6.41 | N2: 1.45 | O2: 9.89 | P2: 6.41 | Q2: 31.96 | R2: 972 | S2: 15
A3: Endpoint / Host / EC2 | B3: EDR/XDR telemetry | C3: TRUE | D3: TRUE | E3: TRUE | F3: XDR → Sentinel integration | G3: SIEM + SIEM data lake | H3: Completed | I3: MS Defender for Endpoint | J3: DeviceProcessEvents | K3: 1 | L3: 27 | M3: 14.46 | N3: 4.67 | O3: 17.5 | P3: 14.46 | Q3: 72.05 | R3: 2192 | S3: 34
A4: Endpoint / Host / EC2 | B4: EDR/XDR telemetry | C4: TRUE | D4: TRUE | E4: TRUE | F4: XDR → Sentinel integration | G4: SIEM + SIEM data lake | H4: Completed | I4: MS Defender for Endpoint | J4: DeviceNetworkEvents | K4: 1 | L4: 27 | M4: 5.12 | N4: 0.92 | O4: 7.6 | P4: 5.12 | Q4: 25.53 | R4: 776 | S4: 12
A5: Endpoint / Host / EC2 | B5: EDR/XDR telemetry | C5: TRUE | D5: TRUE | E5: TRUE | F5: XDR → Sentinel integration | G5: SIEM + SIEM data lake | H5: Completed | I5: MS Defender for Endpoint | J5: DeviceLogonEvents | K5: 1 | L5: 27 | M5: 0.22 | N5: 0.1 | O5: 0.41 | P5: 0.22 | Q5: 1.08 | R5: 33 | S5: 1
A6: Endpoint / Host / EC2 | B6: EDR/XDR telemetry | C6: TRUE | D6: TRUE | E6: TRUE | F6: XDR → Sentinel integration | G6: SIEM + SIEM data lake | H6: Completed | I6: MS Defender for Endpoint | J6: DeviceRegistryEvents | K6: 1 | L6: 27 | M6: 1.57 | N6: 0.28 | O6: 3.48 | P6: 1.57 | Q6: 7.82 | R6: 238 | S6: 4
A7: Endpoint / Host / EC2 | B7: EDR/XDR telemetry | C7: TRUE | D7: TRUE | E7: TRUE | F7: XDR → Sentinel integration | G7: SIEM + SIEM data lake | H7: Completed | I7: MS Defender for Endpoint | J7: DeviceFileEvents | K7: 1 | L7: 28 | M7: 5.55 | N7: 1.32 | O7: 13.51 | P7: 5.55 | Q7: 27.65 | R7: 841 | S7: 13
A8: Endpoint / Host / EC2 | B8: Tanium Threat Response alerts | C8: TRUE | D8: TRUE | E8: TRUE | F8: Tanium → Logs Ingestion API / DCR | G8: SIEM + SIEM data lake | H8: Completed | I8: Tanium | J8: TaniumThreatResponse_CL | K8: 1 | L8: 26 | M8: 0 | N8: 0 | O8: 0 | P8: 0 | Q8: 0 | R8: 0 | S8: 0
A9: Endpoint / Host / EC2 | B9: Tanium Audit events | C9: FALSE | D9: TRUE | E9: FALSE | F9: Tanium → Logs Ingestion API / DCR | G9: SIEM data lake | H9: Completed | I9: Tanium | J9: TaniumAuditSource_CL | K9: 1 | L9: 30 | M9: 0.01 | N9: 0.01 | O9: 0.02 | P9: 0.01 | Q9: 0.05 | R9: 2 | S9: 0
A10: Endpoint / Host / EC2 | B10: Tanium Performance | C10: FALSE | D10: FALSE | E10: TRUE | G10: Data platform | H10: On-hold | I10: Tanium | K10: 0
A11: Endpoint / Host / EC2 | B11: OS Logs - Windows | C11: TRUE | D11: TRUE | E11: FALSE | G11: SIEM + SIEM data lake | H11: On-hold | I11: Windows Event Logs: Security, System, Application Windows Defender Firewall Microsoft-Windows-Windows Defender/Operational Microsoft-Windows-PowerShell/Operational Monitoring of critical configuration files (FIM) | J11: Events | K11: 0 | L11: 30 | M11: 0.14 | N11: 0.1 | O11: 0.21 | P11: 0.14 | Q11: 0.71 | R11: 22 | S11: 0
A12: Endpoint / Host / EC2 | B12: OS Logs - Linux | C12: TRUE | D12: TRUE | E12: FALSE | F12: Syslog | G12: SIEM + SIEM data lake | H12: On-hold | I12: Linux OS: Auth / Authpriv Auditd logs Deamon logs Kern logs Cron logs Firewall logs critical configuration files (FIM) | J12: Syslog | K12: 0 | L12: 30 | M12: 3.13 | N12: 0 | O12: 50.73 | P12: 3.13 | Q12: 15.62 | R12: 475 | S12: 7
A13: Endpoint / Host / EC2 OS - Intune Audit / Config Change logs | B13: OS - Intune Audit / Config Change logs | C13: FALSE | D13: FALSE | E13: FALSE | F13: Intune → Sentinel direct | G13: Data Platform | H13: To be onboarded | I13: Intune Diagnostics Settings | J13: Intune - Workspace centralitlog | K13: 0
A14: Powershell logs | B14: PowerShell logs | C14: TRUE | D14: TRUE | E14: FALSE | F14: Tanium Connector | G14: SIEM + SIEM data lake | H14: Completed | I14: Tanium Signals | J14: Already covered under: TaniumThreatResponse_CL | K14: 0
A15: Endpoint / Host / EC2 | B15: OS - Windows Registry Activity | C15: FALSE | D15: TRUE | E15: FALSE | F15: XDR → Sentinel integration | G15: SIEM data lake | H15: Completed | I15: MS Defender for Endpoint | J15: Already covered under: DeviceRegistryEvents | K15: 0
A16: Identity & Access | B16: Directory Services (Entra ID) - sign in & audit logs | C16: TRUE | D16: TRUE | E16: TRUE | F16: EntraID → Sentinel integration | G16: SIEM + SIEM data lake | H16: Completed | I16: EntraID | J16: SigninLogs | K16: 1 | L16: est. | M16: 0.5 | P16: =M16 -> 0.5 | Q16: =ROUND(P16*IF(C16,PriceAnalytics,PriceLake),2) -> 2.49 | R16: =ROUND(P16*IF(C16,PriceAnalytics,PriceLake)*DaysPerMonth,0) -> 76 | S16: =ROUND(M16*IF(C16,MAX(RetAnalyticsTotal-FreeRetDays,0),RetLakeTotal)/6*PriceStorage,0) -> 1
A17: Identity & Access | B17: Directory Services (AD) - sign-in & audit logs | C17: TRUE | D17: TRUE | E17: TRUE | F17: Azure ARC Agent for DC | G17: SIEM + SIEM data lake | H17: Completed | I17: Active Directory | J17: SecurityEvents | K17: 1 | L17: 30 | M17: 16.29 | N17: 3.83 | O17: 21.91 | P17: 16.29 | Q17: 81.19 | R17: 2470 | S17: 38
A18: Identity & Access | B18: Directory Services (AD + Entra ID) - authentication events | C18: TRUE | D18: TRUE | E18: TRUE | F18: Azure ARC Agent for DC EntraID → Sentinel integration | G18: SIEM + SIEM data lake | H18: Completed | I18: EntraID Active Directory | J18: Already covered under: SigninLogs SecurityEvents | K18: 0
A19: Identity & Access | B19: Directory Services (AD + Entra ID) - Kerberos ticket operations | C19: TRUE | D19: TRUE | E19: TRUE | F19: Azure ARC Agent for DC | G19: SIEM + SIEM data lake | H19: Completed | I19: Active Directory | J19: Already covered under: SecurityEvents | K19: 0
A20: Identity & Access | B20: Directory Services (AD + Entra ID) - replication & LDAP events | C20: TRUE | D20: TRUE | E20: TRUE | F20: Azure ARC Agent for DC EntraID → Sentinel integration | G20: SIEM + SIEM data lake | H20: Completed | I20: EntraID Active Directory | J20: Already covered under: SigninLogs SecurityEvents | K20: 0
A21: Identity & Access | B21: Multi-factor authentication logs | C21: TRUE | D21: TRUE | E21: TRUE | F21: Azure ARC Agent for DC EntraID → Sentinel integration | G21: SIEM + SIEM data lake | H21: Completed | I21: EntraID Active Directory | J21: Already covered under: SigninLogs SecurityEvents | K21: 0
A22: Identity & Access | B22: Directory Services (AD + Entra ID) - authentication events | C22: TRUE | D22: TRUE | E22: TRUE | F22: Azure ARC Agent for DC EntraID → Sentinel integration | G22: SIEM + SIEM data lake | H22: Completed | I22: EntraID Active Directory | J22: Already covered under: SigninLogs SecurityEvents | K22: 0
A23: Identity & Access | B23: Directory Services (AD + Entra ID) - Kerberos ticket operations | C23: TRUE | D23: TRUE | E23: TRUE | F23: Azure ARC Agent for DC | G23: SIEM + SIEM data lake | H23: Completed | I23: Active Directory | J23: Already covered under: SecurityEvents | K23: 0
A24: Identity & Access | B24: Directory Services (AD + Entra ID) - replication & LDAP events | C24: TRUE | D24: TRUE | E24: TRUE | F24: Azure ARC Agent for DC EntraID → Sentinel integration | G24: SIEM + SIEM data lake | H24: Completed | I24: EntraID Active Directory | J24: Already covered under: SigninLogs SecurityEvents | K24: 0
A25: Identity & Access | B25: Multi-factor authentication logs | C25: TRUE | D25: TRUE | E25: TRUE | F25: Azure ARC Agent for DC EntraID → Sentinel integration | G25: SIEM + SIEM data lake | H25: Completed | I25: EntraID Active Directory | J25: Already covered under: SigninLogs SecurityEvents | K25: 0
A26: Identity & Access | B26: Privileged Access Management (PAM) logs | C26: TRUE | D26: TRUE | E26: TRUE | F26: EntraID → Sentinel integration | G26: SIEM + SIEM data lake | H26: Completed | I26: PIM for EntraID | J26: AuditLogs | where LoggedByService contains "PIM" | K26: 1 | L26: 30 | M26: 0.57 | N26: 0.05 | O26: 1.69 | P26: 0.57 | Q26: 2.85 | R26: 87 | S26: 1
A27: Identity & Access | B27: VPN/remote access logs | C27: FALSE | D27: TRUE | E27: TRUE | F27: Syslog | G27: SIEM + SIEM data lake | H27: To be onboarded | I27: Checkpoint Management console | K27: 1 | L27: est. | M27: 0.5 | P27: =M27 -> 0.5 | Q27: =ROUND(P27*IF(C27,PriceAnalytics,PriceLake),2) -> 0.09 | R27: =ROUND(P27*IF(C27,PriceAnalytics,PriceLake)*DaysPerMonth,0) -> 3 | S27: =ROUND(M27*IF(C27,MAX(RetAnalyticsTotal-FreeRetDays,0),RetLakeTotal)/6*PriceStorage,0) -> 1
A28: Identity & Access | B28: CyberArk Audit logs | C28: TRUE | D28: TRUE | E28: FALSE | F28: CCF | G28: SIEM + SIEM data lake | H28: Completed | I28: Idira | J28: CyberArk_AuditEvents_CL | K28: 1 | L28: 30 | M28: 0.01 | N28: 0 | O28: 0.1 | P28: 0.01 | Q28: 0.07 | R28: 2 | S28: 0
A29: Identity & Access | B29: Cisco ISE | C29: TRUE | D29: TRUE | E29: FALSE | F29: Syslog | G29: SIEM + SIEM data lake | H29: To be onboarded | I29: Cisco ISE | K29: 1 | L29: est. | M29: 2 | P29: =M29 -> 2 | Q29: =ROUND(P29*IF(C29,PriceAnalytics,PriceLake),2) -> 9.97 | R29: =ROUND(P29*IF(C29,PriceAnalytics,PriceLake)*DaysPerMonth,0) -> 303 | S29: =ROUND(M29*IF(C29,MAX(RetAnalyticsTotal-FreeRetDays,0),RetLakeTotal)/6*PriceStorage,0) -> 5
A30: Network | B30: Firewall - threat logs | C30: TRUE | D30: TRUE | E30: TRUE | F30: AMA / Syslog | G30: SIEM + SIEM data lake | H30: Completed | I30: Palo Alto Panorama | J30: PaloAltoThreat_CL | K30: 1 | L30: 30 | M30: 23.33 | N30: 2.81 | O30: 159.65 | P30: 23.33 | Q30: 116.28 | R30: 3537 | S30: 55
A31: Network | B31: Firewall - web proxy logs (URL logs) - RawData | C31: FALSE | D31: TRUE | E31: TRUE | F31: AMA / Syslog | G31: SIEM + SIEM data lake | H31: Completed | I31: Palo Alto Panorama | J31: PaloAltoUrlFiltering_Raw_CL | K31: 1 | L31: 12 | M31: 48.4 | N31: 2.14 | O31: 66.6 | P31: 48.4 | Q31: 8.64 | R31: 263 | S31: 65
A32: Network | B32: Firewall - web proxy logs (URL logs) - Extracted Fields | C32: TRUE | D32: FALSE | E32: FALSE | F32: AMA / Syslog | G32: SIEM + SIEM data lake | H32: In Progress | I32: Palo Alto Panorama | J32: PaloAltoUrlFiltering_CL | K32: 2 | L32: est. | M32: 14.52 | P32: =M32 -> 14.52 | Q32: =ROUND(P32*IF(C32,PriceAnalytics,PriceLake),2) -> 72.37 | R32: =ROUND(P32*IF(C32,PriceAnalytics,PriceLake)*DaysPerMonth,0) -> 2201 | S32: =ROUND(M32*IF(C32,MAX(RetAnalyticsTotal-FreeRetDays,0),RetLakeTotal)/6*PriceStorage,0) -> 34
A33: Network | B33: Firewall - traffic logs - RawData | C33: FALSE | D33: TRUE | E33: TRUE | F33: AMA / Syslog | G33: SIEM + SIEM data lake | H33: Completed | I33: Palo Alto Panorama | J33: PaloAltoTraffic_Raw_CL | K33: 1 | L33: 13 | M33: 112.14 | N33: 6.88 | O33: 186.15 | P33: 112.14 | Q33: 20.02 | R33: 609 | S33: 150
A34: Network | B34: Firewall - traffic logs - Extracted Fields | C34: TRUE | D34: FALSE | E34: FALSE | F34: AMA / Syslog | G34: SIEM + SIEM data lake | H34: In Progress | I34: Palo Alto Panorama | J34: PaloAltoTraffic_CL | K34: 2 | L34: est. | M34: 28.04 | P34: =M34 -> 28.04 | Q34: =ROUND(P34*IF(C34,PriceAnalytics,PriceLake),2) -> 139.76 | R34: =ROUND(P34*IF(C34,PriceAnalytics,PriceLake)*DaysPerMonth,0) -> 4251 | S34: =ROUND(M34*IF(C34,MAX(RetAnalyticsTotal-FreeRetDays,0),RetLakeTotal)/6*PriceStorage,0) -> 66
A35: Network | B35: Firewall - audit logs | C35: FALSE | D35: FALSE | E35: TRUE | F35: Syslog | G35: Data Platform | H35: To be onboarded | I35: Palo Alto Panorama | K35: 0
A36: Network | B36: DNS query/response logs | C36: FALSE | D36: TRUE | E36: TRUE | G36: SIEM data lake | H36: On-hold | K36: 1 | L36: est. | M36: 10 | P36: =M36 -> 10 | Q36: =ROUND(P36*IF(C36,PriceAnalytics,PriceLake),2) -> 1.79 | R36: =ROUND(P36*IF(C36,PriceAnalytics,PriceLake)*DaysPerMonth,0) -> 54 | S36: =ROUND(M36*IF(C36,MAX(RetAnalyticsTotal-FreeRetDays,0),RetLakeTotal)/6*PriceStorage,0) -> 13
A37: Network | B37: Network device Audit logs | C37: FALSE | D37: FALSE | E37: TRUE | G37: Data Platform | H37: On-hold | K37: 0
A38: Network | B38: DHCP lease logs | C38: FALSE | D38: TRUE | E38: FALSE | G38: SIEM + SIEM data lake | H38: On-hold | K38: 1 | L38: est. | M38: 0.1 | P38: =M38 -> 0.1 | Q38: =ROUND(P38*IF(C38,PriceAnalytics,PriceLake),2) -> 0.02 | R38: =ROUND(P38*IF(C38,PriceAnalytics,PriceLake)*DaysPerMonth,0) -> 1 | S38: =ROUND(M38*IF(C38,MAX(RetAnalyticsTotal-FreeRetDays,0),RetLakeTotal)/6*PriceStorage,0) -> 0
A39: Cloud Infrastructure | B39: Cloud provider audit logs (e.g. AWS CloudTrail, Azure Activity Logs) | C39: FALSE | D39: TRUE | E39: TRUE | F39: AWS | G39: SIEM data lake | H39: On-hold | I39: AWS CloudTrail | K39: 1 | L39: est. | M39: 3 | P39: =M39 -> 3 | Q39: =ROUND(P39*IF(C39,PriceAnalytics,PriceLake),2) -> 0.54 | R39: =ROUND(P39*IF(C39,PriceAnalytics,PriceLake)*DaysPerMonth,0) -> 16 | S39: =ROUND(M39*IF(C39,MAX(RetAnalyticsTotal-FreeRetDays,0),RetLakeTotal)/6*PriceStorage,0) -> 4
A40: Cloud Infrastructure | B40: Cloud provider audit logs (e.g. AWS CloudTrail, Azure Activity Logs) | C40: FALSE | D40: TRUE | E40: TRUE | F40: AWS | G40: SIEM data lake | H40: Completed | I40: Azure Activity Logs | J40: AzureActivity | K40: 1 | L40: 30 | M40: 0.09 | N40: 0.05 | O40: 0.15 | P40: 0 | Q40: 0 | R40: 0 | S40: 0
...

Sheet Summary
B1: Pay as you go | C1: CHFperMonth | D1: LakeCHFperMonth | E1: TotalCHFperMonth | F1: TotalCHFperYear | H1: From Log Types (cumulative tiers) | I1: Analytics GB/day | J1: Lake GB/day | K1: Lake ingest CHF/month | L1: Storage CHF/month
B2: Tier 1 | C2: =$I2*PriceAnalytics*DaysPerMonth -> 15710.908 | D2: =$K2+$L2 -> 1480 | E2: =C2+D2 -> 17190.908 | F2: =E2*12 -> 206290.9 | H2: Tier 1 | I2: =SUMIFS('Log Types'!$P$2:$P$80,'Log Types'!$K$2:$K$80,">=1",'Log Types'!$K$2:$K$80,"<=1",'Log Types'!$C$2:$C$80,TRUE) -> 103.63 | J2: =SUMIFS('Log Types'!$P$2:$P$80,'Log Types'!$K$2:$K$80,">=1",'Log Types'!$K$2:$K$80,"<=1",'Log Types'!$C$2:$C$80,FALSE) -> 181.15 | K2: =SUMIFS('Log Types'!$R$2:$R$80,'Log Types'!$K$2:$K$80,">=1",'Log Types'!$K$2:$K$80,"<=1",'Log Types'!$C$2:$C$80,FALSE) -> 986 | L2: =SUMIFS('Log Types'!$S$2:$S$80,'Log Types'!$K$2:$K$80,">=1",'Log Types'!$K$2:$K$80,"<=1") -> 494
B3: Tier 2 | C3: =$I3*PriceAnalytics*DaysPerMonth -> 23464.028 | D3: =$K3+$L3 -> 1619 | E3: =C3+D3 -> 25083.028 | F3: =E3*12 -> 300996.34 | H3: Tier 2 | I3: =SUMIFS('Log Types'!$P$2:$P$80,'Log Types'!$K$2:$K$80,">=1",'Log Types'!$K$2:$K$80,"<=2",'Log Types'!$C$2:$C$80,TRUE) -> 154.77 | J3: =SUMIFS('Log Types'!$P$2:$P$80,'Log Types'!$K$2:$K$80,">=1",'Log Types'!$K$2:$K$80,"<=2",'Log Types'!$C$2:$C$80,FALSE) -> 184.15 | K3: =SUMIFS('Log Types'!$R$2:$R$80,'Log Types'!$K$2:$K$80,">=1",'Log Types'!$K$2:$K$80,"<=2",'Log Types'!$C$2:$C$80,FALSE) -> 1002 | L3: =SUMIFS('Log Types'!$S$2:$S$80,'Log Types'!$K$2:$K$80,">=1",'Log Types'!$K$2:$K$80,"<=2") -> 617
B4: Tier 3 | C4: =$I4*PriceAnalytics*DaysPerMonth -> 24764.806 | D4: =$K4+$L4 -> 1658 | E4: =C4+D4 -> 26422.806 | F4: =E4*12 -> 317073.67 | H4: Tier 3 | I4: =SUMIFS('Log Types'!$P$2:$P$80,'Log Types'!$K$2:$K$80,">=1",'Log Types'!$K$2:$K$80,"<=3",'Log Types'!$C$2:$C$80,TRUE) -> 163.35 | J4: =SUMIFS('Log Types'!$P$2:$P$80,'Log Types'!$K$2:$K$80,">=1",'Log Types'!$K$2:$K$80,"<=3",'Log Types'!$C$2:$C$80,FALSE) -> 187.15 | K4: =SUMIFS('Log Types'!$R$2:$R$80,'Log Types'!$K$2:$K$80,">=1",'Log Types'!$K$2:$K$80,"<=3",'Log Types'!$C$2:$C$80,FALSE) -> 1018 | L4: =SUMIFS('Log Types'!$S$2:$S$80,'Log Types'!$K$2:$K$80,">=1",'Log Types'!$K$2:$K$80,"<=3") -> 640
B6: 50 GB/day | C6: CHFperMonth | D6: LakeCHFperMonth | E6: TotalCHFperMonth | F6: TotalCHFperYear | H6: Commitment tier (analytics tier only) | I6: GB per day | J6: CHF per day | K6: CHF per GB | L6: Discount vs PAYG
B7: Tier 1 | C7: =MAX($J$8,$I2*$K$8)*DaysPerMonth -> 12095.908 | D7: =$K2+$L2 -> 1480 | E7: =C7+D7 -> 13575.908 | F7: =E7*12 -> 162910.9 | H7: Pay as you go | K7: =PriceAnalytics -> 4.9843 | L7: =1-K7/$K$7 -> 0
B8: Tier 2 | C8: =MAX($J$8,$I3*$K$8)*DaysPerMonth -> 18065.075 | D8: =$K3+$L3 -> 1619 | E8: =C8+D8 -> 19684.075 | F8: =E8*12 -> 236208.9 | H8: 50 GB/day (promo) | I8: 50 | J8: 191.8719 | K8: =J8/I8 -> 3.837438 | L8: =1-K8/$K$7 -> 0.2300949
B9: Tier 3 | C9: =MAX($J$8,$I4*$K$8)*DaysPerMonth -> 19066.551 | D9: =$K4+$L4 -> 1658 | E9: =C9+D9 -> 20724.551 | F9: =E9*12 -> 248694.61 | H9: 100 GB/day | I9: 100 | J9: 322.7217 | K9: =J9/I9 -> 3.227217 | L9: =1-K9/$K$7 -> 0.35252352
H10: 200 GB/day | I10: 200 | J10: 597.2148 | K10: =J10/I10 -> 2.986074 | L10: =1-K10/$K$7 -> 0.40090404
B11: 100 GB/day | C11: CHFperMonth | D11: LakeCHFperMonth | E11: TotalCHFperMonth | F11: TotalCHFperYear | H11: Fixed price per day, paid even on quieter days. GB above the tier cost the tier's own CHF per GB.
B12: Tier 1 | C12: =MAX($J$9,$I2*$K$9)*DaysPerMonth -> 10172.443 | D12: =$K2+$L2 -> 1480 | E12: =C12+D12 -> 11652.443 | F12: =E12*12 -> 139829.32
B13: Tier 2 | C13: =MAX($J$9,$I3*$K$9)*DaysPerMonth -> 15192.406 | D13: =$K3+$L3 -> 1619 | E13: =C13+D13 -> 16811.406 | F13: =E13*12 -> 201736.88 | H13: Prices and settings (CHF, Switzerland North list prices, Oct 2026)
B14: Tier 3 | C14: =MAX($J$9,$I4*$K$9)*DaysPerMonth -> 16034.629 | D14: =$K4+$L4 -> 1658 | E14: =C14+D14 -> 17692.629 | F14: =E14*12 -> 212311.55 | H14: Analytics tier, pay as you go (per GB) | I14: 4.9843
H15: Data lake ingestion + processing (per GB) | I15: 0.1785
B16: 200 GB/day | C16: CHFperMonth | D16: LakeCHFperMonth | E16: TotalCHFperMonth | F16: TotalCHFperYear | H16: Data lake storage (per compressed GB per month, 6:1) | I16: 0.022
B17: Tier 1 | C17: =MAX($J$10,$I2*$K$10)*DaysPerMonth -> 18165.284 | D17: =$K2+$L2 -> 1480 | E17: =C17+D17 -> 19645.284 | F17: =E17*12 -> 235743.4 | H17: Total retention of analytics tables (days) | I17: 730
B18: Tier 2 | C18: =MAX($J$10,$I3*$K$10)*DaysPerMonth -> 18165.284 | D18: =$K3+$L3 -> 1619 | E18: =C18+D18 -> 19784.284 | F18: =E18*12 -> 237411.4 | H18: Total retention of lake-only tables (days) | I18: 365
B19: Tier 3 | C19: =MAX($J$10,$I4*$K$10)*DaysPerMonth -> 18165.284 | D19: =$K4+$L4 -> 1658 | E19: =C19+D19 -> 19823.284 | F19: =E19*12 -> 237879.4 | H19: Analytics retention included in the price (days) | I19: 90
H20: Days per month | I20: =365/12 -> 30.416667
B21: Cheapest option | C21: Option | D21: TotalCHFperMonth | E21: TotalCHFperYear | F21: Saving/year vs PAYG
B22: Tier 1 | C22: =IF(E2=MIN(E2,E7,E12,E17),"Pay as you go",IF(E7=MIN(E2,E7,E12,E17),"50 GB/day",IF(E12=MIN(E2,E7,E12,E17),"100 GB/day","200 GB/day"))) -> 100 GB/day | D22: =MIN(E2,E7,E12,E17) -> 11652.443 | E22: =D22*12 -> 139829.32 | F22: =(E2-D22)*12 -> 66461.577
B23: Tier 2 | C23: =IF(E3=MIN(E3,E8,E13,E18),"Pay as you go",IF(E8=MIN(E3,E8,E13,E18),"50 GB/day",IF(E13=MIN(E3,E8,E13,E18),"100 GB/day","200 GB/day"))) -> 100 GB/day | D23: =MIN(E3,E8,E13,E18) -> 16811.406 | E23: =D23*12 -> 201736.88 | F23: =(E3-D23)*12 -> 99259.464
B24: Tier 3 | C24: =IF(E4=MIN(E4,E9,E14,E19),"Pay as you go",IF(E9=MIN(E4,E9,E14,E19),"50 GB/day",IF(E14=MIN(E4,E9,E14,E19),"100 GB/day","200 GB/day"))) -> 100 GB/day | D24: =MIN(E4,E9,E14,E19) -> 17692.629 | E24: =D24*12 -> 212311.55 | F24: =(E4-D24)*12 -> 104762.12
B26: Tiers are cumulative: Tier 2 = cost tiers 1 + 2, Tier 3 = cost tiers 1 + 2 + 3 (column K of Log Types; 0 is out of scope).
B27: CHFperMonth = Sentinel analytics tier, the part a commitment tier discounts. LakeCHFperMonth = data lake ingestion + processing, plus storage of analytics data after 90 days and of lake-only tables, at full retention. It's the same whichever pricing you pick.
B28: A commitment tier applies per workspace and has a 31-day minimum. The cheapest total per tier is highlighted in green.
B29: The 50 GB/day tier is a promotion: sign up by 31 Dec 2026; the price is locked only until 31 Mar 2027.
B30: List prices excluding VAT. The Microsoft 365 E5 grant and any agreement discount are not deducted.

Sheet Estimate notes
B1: Estimate notes
B3: est. | C3: Pale yellow cells in columns L-S of Log Types are estimates. Change the GB/day in column M (blue), or tick/untick Detection, and the costs on that row update.
C4: Destination follows your rule: Detection ticked = analytics, otherwise data lake. Rows with data already were kept, except where noted below.
C5: Ingested today but not in your table: BehaviorAnalytics (UEBA) about 1.34 GB/day, CHF ~203/month; EmailUrlInfo about 0.14 GB/day, CHF ~21/month. Out of scope (tier 0) but still ingesting: Syslog about CHF 475/month, Event about CHF 22/month.
B7: Row | C7: Sub-category | D7: Table assumed | E7: Destination | F7: GB/day used | G7: Range (GB/day) | H7: Basis
B8: 16 | C8: Directory Services (Entra ID) - sign in & audit logs | D8: SigninLogs | E8: Analytics | F8: 0.5 | G8: 0.2 - 1.5 | H8: Interactive Entra ID sign-ins, sized for ~1,500-2,500 users (from your Defender volumes). SigninLogs doesn't appear in your usage results at all, so it isn't being ingested yet even though the row says Completed - check the Entra ID connector. Non-interactive sign-ins (AADNonInteractiveUserSignInLogs) would add 2-5x this. Covered by the Microsoft 365 E5 grant if you have it.
B9: 27 | C9: VPN/remote access logs | D9: Syslog / CommonSecurityLog | E9: Data lake | F9: 0.5 | G9: 0.1 - 1 | H9: Check Point VPN logins and session events only. Detection isn't ticked, so it's priced in the data lake; in analytics it would be about CHF 76/month.
B10: 29 | C10: Cisco ISE | D10: Syslog / CommonSecurityLog | E10: Analytics | F10: 2 | G10: 0.5 - 10 | H10: RADIUS authentication + accounting. Most of the volume is accounting and successful logins; keep failed logins, TACACS+ admin logins and config changes in analytics and split the rest to the lake to cut it.
B11: 30 | C11: Firewall - threat logs | D11: PaloAltoThreat_CL | E11: Analytics (measured) | F11: 23.33 | G11: - | H11: Measured: from your KQL results (last 30 days).
B12: 31 | C12: Firewall - web proxy logs (URL logs) - RawData | D12: PaloAltoUrlFiltering_Raw_CL | E12: Data lake (measured) | F12: 48.4 | G12: - | H12: Your lake query output was one column off from the headers. Moved so P-S mean the same as on every other row: billable GB/day, CHF/day, CHF/month (lake ingestion + processing), lake storage when full. Values unchanged.
B13: 32 | C13: Firewall - web proxy logs (URL logs) - Extracted Fields | D13: PaloAltoUrlFiltering_CL | E13: Analytics | F13: 14.52 | G13: 10 - 20 | H13: Extracted fields = about 30% of the raw URL table (48.4 GB/day). Measure the real share with the SlimShare query before relying on it.
B14: 33 | C14: Firewall - traffic logs - RawData | D14: PaloAltoTraffic_Raw_CL | E14: Data lake (measured) | F14: 112.14 | G14: - | H14: Your lake query output was one column off from the headers. Moved so P-S mean the same as on every other row. Values unchanged.
B15: 34 | C15: Firewall - traffic logs - Extracted Fields | D15: PaloAltoTraffic_CL | E15: Analytics | F15: 28.04 | G15: 20 - 40 | H15: Extracted fields = about 25% of raw traffic (112.14 GB/day). Filtering rows as well (e.g. internal allowed traffic) brings it down further.
B16: 36 | C16: DNS query/response logs | D16: DNS server logs (ASIM DNS) | E16: Data lake | F16: 10 | G16: 3 - 25 | H16: On-premises DNS servers, one record per query, ~1,500-2,500 clients. Depends a lot on whether servers and internal lookups are included.
B17: 38 | C17: DHCP lease logs | D17: DHCP server logs | E17: Data lake | F17: 0.1 | G17: 0.05 - 0.5 | H17: One record per lease event.
B18: 39 | C18: Cloud provider audit logs (e.g. AWS CloudTrail, Azure Activity Logs) | D18: AWSCloudTrail | E18: Data lake | F18: 3 | G18: 1 - 5 | H18: Management events only; S3/Lambda data events can be 10x more. Detection isn't ticked, so it's priced in the data lake; in analytics it would be about CHF 455/month.
B19: 40 | C19: Cloud provider audit logs (e.g. AWS CloudTrail, Azure Activity Logs) | D19: AzureActivity | E19: Analytics (measured) | F19: 0.09 | G19: - | H19: Measured: from your KQL results. Free in analytics, so leave it there (lake ingestion would not be free).
... B33: 57 | C33: Custom application logs (candidates for detecting malicious activity) | D33: Custom tables (_CL) | E33: Analytics | F33: 1 | G33: 0.2 - 5 | H33: Security-relevant application events only.
B34: 58 | C34: Database sign-in events | D34: Database audit logs | E34: Analytics | F34: 0.2 | G34: 0.05 - 1
B35: 59 | C35: Database permission changes | D35: Database audit logs | E35: Analytics | F35: 0.01 | G35: < 0.05
B36: 60 | C36: Database data access and export | D36: Database audit logs | E36: Analytics | F36: 2 | G36: 0.5 - 20 | H36: Depends on how much read (SELECT) auditing is switched on.
B37: 61 | C37: Web Application Firewall traffic | D37: WAF logs | E37: Analytics | F37: 3 | G37: 1 - 15 | H37: Every request; candidate for the data lake if detection only needs the threat logs.
B38: 62 | C38: Web Application Firewall threat logs | D38: WAF logs | E38: Analytics | F38: 0.2 | G38: 0.05 - 1 | H38: Matched and blocked requests only.
B39: 63 | C39: Application administrator activity | D39: Application audit logs | E39: Analytics | F39: 0.05 | G39: 0.01 - 0.2
B40: 64 | C40: Database administrator activity | D40: Database audit logs | E40: Analytics | F40: 0.1 | G40: 0.02 - 0.5
B41: 65 | C41: Config change | D41: Application audit logs | E41: Analytics | F41: 0.02 | G41: < 0.1
B42: 66 | C42: Log stopped | D42: - | E42: Analytics | F42: 0 | G42: ~0 | H42: A detection on missing data; adds no volume.
B43: 68 | C43: Web service access logs (e.g. Apache, Nginx, IIS) | D43: Web server logs | E43: Data lake | F43: 3 | G43: 1 - 10 | H43: One line per request. Assumed the same size as the highly critical apps; scale by the number of apps.
B44: 69 | C44: API gateway logs | D44: API gateway logs | E44: Analytics | F44: 2 | G44: 0.5 - 10 | H44: One record per API call. Assumed the same size as the highly critical apps; scale by the number of apps.
B45: 70 | C45: Custom application logs (candidates for detecting malicious activity) | D45: Custom tables (_CL) | E45: Analytics | F45: 1 | G45: 0.2 - 5 | H45: Security-relevant application events only. Assumed the same size as the highly critical apps; scale by the number of apps.
B46: 71 | C46: Database sign-in events | D46: Database audit logs | E46: Analytics | F46: 0.2 | G46: 0.05 - 1 | H46: Assumed the same size as the highly critical apps; scale by the number of apps.
B47: 72 | C47: Database permission changes | D47: Database audit logs | E47: Analytics | F47: 0.01 | G47: < 0.05 | H47: Assumed the same size as the highly critical apps; scale by the number of apps.
B48: 73 | C48: Database data access and export | D48: Database audit logs | E48: Analytics | F48: 2 | G48: 0.5 - 20 | H48: Depends on how much read (SELECT) auditing is switched on. Assumed the same size as the highly critical apps; scale by the number of apps.
B49: 74 | C49: Web Application Firewall traffic | D49: WAF logs | E49: Analytics | F49: 3 | G49: 1 - 15 | H49: Every request; candidate for the data lake if detection only needs the threat logs. Assumed the same size as the highly critical apps; scale by the number of apps.
B50: 75 | C50: Web Application Firewall threat logs | D50: WAF logs | E50: Analytics | F50: 0.2 | G50: 0.05 - 1 | H50: Matched and blocked requests only. Assumed the same size as the highly critical apps; scale by the number of apps.
B51: 76 | C51: Application administrator activity | D51: Application audit logs | E51: Analytics | F51: 0.05 | G51: 0.01 - 0.2 | H51: Assumed the same size as the highly critical apps; scale by the number of apps.
B52: 77 | C52: Database administrator activity | D52: Database audit logs | E52: Analytics | F52: 0.1 | G52: 0.02 - 0.5 | H52: Assumed the same size as the highly critical apps; scale by the number of apps.
B53: 78 | C53: Config change | D53: Application audit logs | E53: Analytics | F53: 0.02 | G53: < 0.1 | H53: Assumed the same size as the highly critical apps; scale by the number of apps.
B54: 79 | C54: Log stopped | D54: - | E54: Analytics | F54: 0 | G54: ~0 | H54: A detection on missing data; adds no volume. Assumed the same size as the highly critical apps; scale by the number of apps.
